<?xml version="1.0" ?>
<!-- Generated using onshape-to-robot -->
<!-- Onshape https://cad.onshape.com/documents/358a5562c24681b2e35f059a/w/975730febe68bc97ce3f2f6d/e/261d0e36edc63293f192658b -->
<robot name="4banhomni">
  <!-- Link chassis -->
  <link name="chassis">
    <inertial>
      <origin xyz="0.000385741 -0.000525851 0.0330364" rpy="0 0 0"/>
      <mass value="0.332505"/>
      <inertia ixx="0.00101221" ixy="-5.71129e-07" ixz="-7.85419e-07" iyy="0.00101221" iyz="-7.85419e-07" izz="0.00181553"/>
    </inertial>
    <!-- Part chassis -->
    <visual>
      <origin xyz="0.000289337 -0.000622255 0.0100389" rpy="-3.57353e-16 2.97332e-15 0.785398"/>
      <geometry>
        <mesh filename="package://assets/chassis.stl"/>
      </geometry>
      <material name="chassis_material">
        <color rgba="0.615686 0.811765 0.929412 1"/>
      </material>
    </visual>
    <collision>
      <origin xyz="0.000289337 -0.000622255 0.0100389" rpy="-3.57353e-16 2.97332e-15 0.785398"/>
      <geometry>
        <mesh filename="package://assets/chassis.stl"/>
      </geometry>
    </collision>
  </link>
  <!-- Link omni_wheel -->
  <link name="omni_wheel">
    <inertial>
      <origin xyz="8.57539e-19 -1.25703e-18 -0.006" rpy="0 0 0"/>
      <mass value="0.0187413"/>
      <inertia ixx="3.45051e-06" ixy="2.12654e-37" ixz="-1.45049e-37" iyy="3.45051e-06" iyz="1.45388e-37" izz="6.18323e-06"/>
    </inertial>
    <!-- Part omni_wheel -->
    <visual>
      <origin xyz="0 0 -0.012" rpy="-1.5708 -2.46991e-32 1.54074e-33"/>
      <geometry>
        <mesh filename="package://assets/omni_wheel.stl"/>
      </geometry>
      <material name="omni_wheel_material">
        <color rgba="0.615686 0.811765 0.929412 1"/>
      </material>
    </visual>
    <collision>
      <origin xyz="0 0 -0.012" rpy="-1.5708 -2.46991e-32 1.54074e-33"/>
      <geometry>
        <mesh filename="package://assets/omni_wheel.stl"/>
      </geometry>
    </collision>
  </link>
  <!-- Joint from chassis to omni_wheel -->
  <joint name="wheel_1" type="continuous">
    <origin xyz="-0.111248 -0.000622255 0.0250389" rpy="1.5708 -7.63278e-17 -1.5708"/>
    <parent link="chassis"/>
    <child link="omni_wheel"/>
    <axis xyz="0 0 1"/>
    <limit effort="10" velocity="10"/>
  </joint>
  <!-- Link omni_wheel_2 -->
  <link name="omni_wheel_2">
    <inertial>
      <origin xyz="8.57539e-19 -1.25703e-18 -0.006" rpy="0 0 0"/>
      <mass value="0.0187413"/>
      <inertia ixx="3.45051e-06" ixy="2.12654e-38" ixz="-7.74105e-39" iyy="3.45051e-06" iyz="-8.84188e-38" izz="6.18323e-06"/>
    </inertial>
    <!-- Part omni_wheel_2 -->
    <visual>
      <origin xyz="0 0 -0.012" rpy="-1.5708 5.9335e-34 2.24267e-33"/>
      <geometry>
        <mesh filename="package://assets/omni_wheel.stl"/>
      </geometry>
      <material name="omni_wheel_2_material">
        <color rgba="0.615686 0.811765 0.929412 1"/>
      </material>
    </visual>
    <collision>
      <origin xyz="0 0 -0.012" rpy="-1.5708 5.9335e-34 2.24267e-33"/>
      <geometry>
        <mesh filename="package://assets/omni_wheel.stl"/>
      </geometry>
    </collision>
  </link>
  <!-- Joint from chassis to omni_wheel_2 -->
  <joint name="wheel_2" type="continuous">
    <origin xyz="0.000289337 0.110915 0.0250389" rpy="-1.5708 -3.78557e-17 -7.67631e-18"/>
    <parent link="chassis"/>
    <child link="omni_wheel_2"/>
    <axis xyz="0 0 1"/>
    <limit effort="10" velocity="10"/>
  </joint>
  <!-- Link omni_wheel_3 -->
  <link name="omni_wheel_3">
    <inertial>
      <origin xyz="4.32699e-18 1.25703e-18 -0.006" rpy="0 0 0"/>
      <mass value="0.0187413"/>
      <inertia ixx="3.45051e-06" ixy="-1.39921e-23" ixz="-1.02865e-37" iyy="3.45051e-06" iyz="2.29633e-37" izz="6.18323e-06"/>
    </inertial>
    <!-- Part omni_wheel_3 -->
    <visual>
      <origin xyz="3.46945e-18 0 0" rpy="1.5708 1.97339e-33 -1.78537e-17"/>
      <geometry>
        <mesh filename="package://assets/omni_wheel.stl"/>
      </geometry>
      <material name="omni_wheel_3_material">
        <color rgba="0.615686 0.811765 0.929412 1"/>
      </material>
    </visual>
    <collision>
      <origin xyz="3.46945e-18 0 0" rpy="1.5708 1.97339e-33 -1.78537e-17"/>
      <geometry>
        <mesh filename="package://assets/omni_wheel.stl"/>
      </geometry>
    </collision>
  </link>
  <!-- Joint from chassis to omni_wheel_3 -->
  <joint name="wheel_3" type="continuous">
    <origin xyz="0.111826 -0.000622255 0.0250389" rpy="-1.5708 -0.80872 -1.5708"/>
    <parent link="chassis"/>
    <child link="omni_wheel_3"/>
    <axis xyz="0 0 1"/>
    <limit effort="10" velocity="10"/>
  </joint>
  <!-- Link omni_wheel_4 -->
  <link name="omni_wheel_4">
    <inertial>
      <origin xyz="-2.61191e-18 1.25703e-18 -0.006" rpy="0 0 0"/>
      <mass value="0.0187413"/>
      <inertia ixx="3.45051e-06" ixy="-2.75896e-22" ixz="-5.2204e-37" iyy="3.45051e-06" iyz="1.1741e-38" izz="6.18323e-06"/>
    </inertial>
    <!-- Part omni_wheel_4 -->
    <visual>
      <origin xyz="-3.46945e-18 0 0" rpy="1.5708 -1.1376e-31 -6.11168e-17"/>
      <geometry>
        <mesh filename="package://assets/omni_wheel.stl"/>
      </geometry>
      <material name="omni_wheel_4_material">
        <color rgba="0.615686 0.811765 0.929412 1"/>
      </material>
    </visual>
    <collision>
      <origin xyz="-3.46945e-18 0 0" rpy="1.5708 -1.1376e-31 -6.11168e-17"/>
      <geometry>
        <mesh filename="package://assets/omni_wheel.stl"/>
      </geometry>
    </collision>
  </link>
  <!-- Joint from chassis to omni_wheel_4 -->
  <joint name="wheel_4" type="continuous">
    <origin xyz="0.000289337 -0.112159 0.0250389" rpy="1.5708 1.29425 -1.09788e-14"/>
    <parent link="chassis"/>
    <child link="omni_wheel_4"/>
    <axis xyz="0 0 1"/>
    <limit effort="10" velocity="10"/>
  </joint>
</robot>
